Workbook

Sheet NRI 2025
A1: Economy | G1: NRIScore | I1: NRIRank | J1: 1.score | K1: 2.score | L1: 3.score | M1: 4.score | N1: 1.rank | O1: 2.rank | P1: 3.rank | Q1: 4.rank | R1: 1.1.score | S1: 1.2.score | T1: 1.3.score | U1: 2.1.score | V1: 2.2.score | W1: 2.3.score | X1: 3.1.score | Y1: 3.2.score | Z1: 3.3.score | AA1: 4.1.score | AB1: 4.2.score | AC1: 4.3.score | AD1: 1.1.rank | AE1: 1.2.rank | AF1: 1.3.rank | AG1: 2.1.rank | AH1: 2.2.rank | AI1: 2.3.rank | AJ1: 3.1.rank | AK1: 3.2.rank | AL1: 3.3.rank | AM1: 4.1.rank | AN1: 4.2.rank | AO1: 4.3.rank | AP1: 1.1.1score | AQ1: 1.1.2score | AR1: 1.1.3score | AS1: 1.1.4score | AT1: 1.1.5score | AU1: 1.1.6score | AV1: 1.2.1score | AW1: 1.2.2score | AX1: 1.2.3score | AY1: 1.2.4score | AZ1: 1.3.1score | BA1: 1.3.2score | BB1: 1.3.3score | BC1: 1.3.4score | BD1: 2.1.1score | BE1: 2.1.2score | BF1: 2.1.3score | BG1: 2.1.4score | BH1: 2.1.5score | BI1: 2.2.1score | BJ1: 2.2.2score | BK1: 2.2.3score | BL1: 2.2.4score | BM1: 2.3.1score | BN1: 2.3.2score | BO1: 2.3.3score | BP1: 2.3.4score | BQ1: 3.1.1score | BR1: 3.1.2score | BS1: 3.1.3score | BT1: 3.1.4score | BU1: 3.2.1score | BV1: 3.2.2score | BW1: 3.2.3score | BX1: 3.2.4score | BY1: 3.2.5score | BZ1: 3.3.1score | CA1: 3.3.2score | CB1: 3.3.3score | CC1: 3.3.4score | CD1: 4.1.1score | CE1: 4.1.2score | CF1: 4.1.3score | CG1: 4.1.4score | CH1: 4.2.1score | CI1: 4.2.2score | CJ1: 4.2.3score | CK1: 4.2.4score | CL1: 4.3.1score | CM1: 4.3.2score | CN1: 4.3.3score | CO1: 4.3.4score | CP1: 4.3.5score | CQ1: 1.1.1rank | CR1: 1.1.2rank | CS1: 1.1.3rank | CT1: 1.1.4rank | CU1: 1.1.5rank | CV1: 1.1.6rank | CW1: 1.2.1rank | CX1: 1.2.2rank | CY1: 1.2.3rank | CZ1: 1.2.4rank | DA1: 1.3.1rank | DB1: 1.3.2rank | DC1: 1.3.3rank | DD1: 1.3.4rank | DE1: 2.1.1rank | DF1: 2.1.2rank | DG1: 2.1.3rank | DH1: 2.1.4rank | DI1: 2.1.5rank | DJ1: 2.2.1rank | DK1: 2.2.2rank | DL1: 2.2.3rank | DM1: 2.2.4rank | DN1: 2.3.1rank | DO1: 2.3.2rank | DP1: 2.3.3rank | DQ1: 2.3.4rank | DR1: 3.1.1rank | DS1: 3.1.2rank | DT1: 3.1.3rank | DU1: 3.1.4rank | DV1: 3.2.1rank | DW1: 3.2.2rank | DX1: 3.2.3rank | DY1: 3.2.4rank | DZ1: 3.2.5rank | EA1: 3.3.1rank | EB1: 3.3.2rank | EC1: 3.3.3rank | ED1: 3.3.4rank | EE1: 4.1.1rank | EF1: 4.1.2rank | EG1: 4.1.3rank | EH1: 4.1.4rank | EI1: 4.2.1rank | EJ1: 4.2.2rank | EK1: 4.2.3rank | EL1: 4.2.4rank | EM1: 4.3.1rank | EN1: 4.3.2rank | EO1: 4.3.3rank | EP1: 4.3.4rank | EQ1: 4.3.5rank
G2: NRI | J2: PILLARS | R2: SUBPILLARS | AP2: 1.1.1 | AQ2: 1.1.2 | AR2: 1.1.3 | AS2: 1.1.4 | AT2: 1.1.5 | AU2: 1.1.6 | AV2: 1.2.1 | AW2: 1.2.2 | AX2: 1.2.3 | AY2: 1.2.4 | AZ2: 1.3.1 | BA2: 1.3.2 | BB2: 1.3.3 | BC2: 1.3.4 | BD2: 2.1.1 | BE2: 2.1.2 | BF2: 2.1.3 | BG2: 2.1.4 | BH2: 2.1.5 | BI2: 2.2.1 | BJ2: 2.2.2 | BK2: 2.2.3 | BL2: 2.2.4 | BM2: 2.3.1 | BN2: 2.3.2 | BO2: 2.3.3 | BP2: 2.3.4 | BQ2: 3.1.1 | BR2: 3.1.2 | BS2: 3.1.3 | BT2: 3.1.4 | BU2: 3.2.1 | BV2: 3.2.2 | BW2: 3.2.3 | BX2: 3.2.4 | BY2: 3.2.5 | BZ2: 3.3.1 | CA2: 3.3.2 | CB2: 3.3.3 | CC2: 3.3.4 | CD2: 4.1.1 | CE2: 4.1.2 | CF2: 4.1.3 | CG2: 4.1.4 | CH2: 4.2.1 | CI2: 4.2.2 | CJ2: 4.2.3 | CK2: 4.2.4 | CL2: 4.3.1 | CM2: 4.3.2 | CN2: 4.3.3 | CO2: 4.3.4 | CP2: 4.3.5 | CQ2: 1.1.1 | CR2: 1.1.2 | CS2: 1.1.3 | CT2: 1.1.4 | CU2: 1.1.5 | CV2: 1.1.6 | CW2: 1.2.1 | CX2: 1.2.2 | CY2: 1.2.3 | CZ2: 1.2.4 | DA2: 1.3.1 | DB2: 1.3.2 | DC2: 1.3.3 | DD2: 1.3.4 | DE2: 2.1.1 | DF2: 2.1.2 | DG2: 2.1.3 | DH2: 2.1.4 | DI2: 2.1.5 | DJ2: 2.2.1 | DK2: 2.2.2 | DL2: 2.2.3 | DM2: 2.2.4 | DN2: 2.3.1 | DO2: 2.3.2 | DP2: 2.3.3 | DQ2: 2.3.4 | DR2: 3.1.1 | DS2: 3.1.2 | DT2: 3.1.3 | DU2: 3.1.4 | DV2: 3.2.1 | DW2: 3.2.2 | DX2: 3.2.3 | DY2: 3.2.4 | DZ2: 3.2.5 | EA2: 3.3.1 | EB2: 3.3.2 | EC2: 3.3.3 | ED2: 3.3.4 | EE2: 4.1.1 | EF2: 4.1.2 | EG2: 4.1.3 | EH2: 4.1.4 | EI2: 4.2.1 | EJ2: 4.2.2 | EK2: 4.2.3 | EL2: 4.2.4 | EM2: 4.3.1 | EN2: 4.3.2 | EO2: 4.3.3 | EP2: 4.3.4 | EQ2: 4.3.5
G3: score | I3: ranking | J3: score | K3: score | L3: score | M3: score | N3: ranking | O3: ranking | P3: ranking | Q3: ranking | R3: score | S3: score | T3: score | U3: score | V3: score | W3: score | X3: score | Y3: score | Z3: score | AA3: score | AB3: score | AC3: score | AD3: ranking | AE3: ranking | AF3: ranking | AG3: ranking | AH3: ranking | AI3: ranking | AJ3: ranking | AK3: ranking | AL3: ranking | AM3: ranking | AN3: ranking | AO3: ranking | AP3: score | AQ3: score | AR3: score | AS3: score | AT3: score | AU3: score | AV3: score | AW3: score | AX3: score | AY3: score | AZ3: score | BA3: score | BB3: score | BC3: score | BD3: score | BE3: score | BF3: score | BG3: score | BH3: score | BI3: score | BJ3: score | BK3: score | BL3: score | BM3: score | BN3: score | BO3: score | BP3: score | BQ3: score | BR3: score | BS3: score | BT3: score | BU3: score | BV3: score | BW3: score | BX3: score | BY3: score | BZ3: score | CA3: score | CB3: score | CC3: score | CD3: score | CE3: score | CF3: score | CG3: score | CH3: score | CI3: score | CJ3: score | CK3: score | CL3: score | CM3: score | CN3: score | CO3: score | CP3: score | CQ3: rank | CR3: rank | CS3: rank | CT3: rank | CU3: rank | CV3: rank | CW3: rank | CX3: rank | CY3: rank | CZ3: rank | DA3: rank | DB3: rank | DC3: rank | DD3: rank | DE3: rank | DF3: rank | DG3: rank | DH3: rank | DI3: rank | DJ3: rank | DK3: rank | DL3: rank | DM3: rank | DN3: rank | DO3: rank | DP3: rank | DQ3: rank | DR3: rank | DS3: rank | DT3: rank | DU3: rank | DV3: rank | DW3: rank | DX3: rank | DY3: rank | DZ3: rank | EA3: rank | EB3: rank | EC3: rank | ED3: rank | EE3: rank | EF3: rank | EG3: rank | EH3: rank | EI3: rank | EJ3: rank | EK3: rank | EL3: rank | EM3: rank | EN3: rank | EO3: rank | EP3: rank | EQ3: rank
A4: NRI 2024 | G4: NRI | I4: NRI | J4: Technology | K4: People | L4: Governance | M4: Impact | N4: Technology | O4: People | P4: Governance | Q4: Impact | R4: Access | S4: Content | T4: Future Technologies | U4: Individuals | V4: Businesses | W4: Governments | X4: Trust | Y4: Regulation | Z4: Inclusion | AA4: Economy | AB4: Quality of Life | AC4: SDG Contribution | AD4: Access | AE4: Content | AF4: Future Technologies | AG4: Individuals | AH4: Businesses | AI4: Governments | AJ4: Trust | AK4: Regulation | AL4: Inclusion | AM4: Economy | AN4: Quality of Life | AO4: SDG Contribution | AP4: Mobile tariffs | AQ4: Handset prices | AR4: FTTH/building Internet subscriptions | AS4: Population covered by at least a 3G mobile network | AT4: International Internet bandwidth | AU4: Internet access in schools | AV4: GitHub commits | AW4: Internet domain registrations | AX4: Mobile apps development | AY4: AI scientific publications | AZ4: Adoption of emerging technologies | BA4: Investment in emerging technologies | BB4: Robot density | BC4: Computer software spending | BD4: Mobile broadband internet traffic within the country | BE4: ICT skills in the education system | BF4: Use of virtual social networks | BG4: Adult literacy rate | BH4: AI talent concentration | BI4: Firms with website | BJ4: Number of venture capital deals invested in AI | BK4: Annual investment in telecommunication services | BL4: Public cloud computing market scale | BM4: Government online services | BN4: Data Capabilities | BO4: Government promotion of emerging technologies | BP4: Gross expenditure on R&D | BQ4: Secure Internet servers | BR4: Cybersecurity | BS4: Online access to financial account | BT4: Internet shopping | BU4: Regulatory quality | BV4: ICT regulatory environment | BW4: Regulation of emerging technologies | BX4: E-commerce legislation | BY4: Privacy protection by law content | BZ4: E-Participation | CA4: Socioeconomic gap in use of digital payments | CB4: Gender gap in Internet use | CC4: Rural gap in use of digital payments | CD4: ICT patent applications | CE4: Domestic market scale | CF4: Technology-enabled work flexibility | CG4: ICT services exports | CH4: Happiness | CI4: Freedom to make life choices | CJ4: Income inequality | CK4: Healthy life expectancy at birth | CL4: SDG 3: Good Health and Well-Being | CM4: SDG 4: Quality Education | CN4: SDG 5: Women's economic opportunity | CO4: SDG 7: Affordable and Clean Energy | CP4: SDG 11: Sustainable Cities and Communities | CQ4: Mobile tariffs | CR4: Handset prices | CS4: FTTH/building Internet subscriptions | CT4: Population covered by at least a 3G mobile network | CU4: International Internet bandwidth | CV4: Internet access in schools | CW4: GitHub commits | CX4: Internet domain registrations | CY4: Mobile apps development | CZ4: AI scientific publications | DA4: Adoption of emerging technologies | DB4: Investment in emerging technologies | DC4: Robot density | DD4: Computer software spending | DE4: Mobile broadband internet traffic within the country | DF4: ICT skills in the education system | DG4: Use of virtual social networks | DH4: Adult literacy rate | DI4: AI talent concentration | DJ4: Firms with website | DK4: Number of venture capital deals invested in AI | DL4: Annual investment in telecommunication services | DM4: Public cloud computing market scale | DN4: Government online services | DO4: Data Capabilities | DP4: Government promotion of emerging technologies | DQ4: Gross expenditure on R&D | DR4: Secure Internet servers | DS4: Cybersecurity | DT4: Online access to financial account | DU4: Internet shopping | DV4: Regulatory quality | DW4: ICT regulatory environment | DX4: Regulation of emerging technologies | DY4: E-commerce legislation | DZ4: Privacy protection by law content | EA4: E-Participation | EB4: Socioeconomic gap in use of digital payments | EC4: Gender gap in Internet use | ED4: Rural gap in use of digital payments | EE4: ICT patent applications | EF4: Domestic market scale | EG4: Technology-enabled work flexibility | EH4: ICT services exports | EI4: Happiness | EJ4: Freedom to make life choices | EK4: Income inequality | EL4: Healthy life expectancy at birth | EM4: SDG 3: Good Health and Well-Being | EN4: SDG 4: Quality Education | EO4: SDG 5: Women's economic opportunity | EP4: SDG 7: Affordable and Clean Energy | EQ4: SDG 11: Sustainable Cities and Communities
G5: nri.score | I5: nri.ranking | J5: 1. | K5: 2. | L5: 3. | M5: 4. | N5: 1. | O5: 2. | P5: 3. | Q5: 4. | R5: 1.1. | S5: 1.2. | T5: 1.3. | U5: 2.1. | V5: 2.2. | W5: 2.3. | X5: 3.1. | Y5: 3.2. | Z5: 3.3. | AA5: 4.1. | AB5: 4.2. | AC5: 4.3. | AD5: 1.1. | AE5: 1.2. | AF5: 1.3. | AG5: 2.1. | AH5: 2.2. | AI5: 2.3. | AJ5: 3.1. | AK5: 3.2. | AL5: 3.3. | AM5: 4.1. | AN5: 4.2. | AO5: 4.3. | AP5: 1.1.1. | AQ5: 1.1.2. | AR5: 1.1.3. | AS5: 1.1.4. | AT5: 1.1.5. | AU5: 1.1.6. | AV5: 1.2.1. | AW5: 1.2.2. | AX5: 1.2.3. | AY5: 1.2.4. | AZ5: 1.3.1. | BA5: 1.3.2. | BB5: 1.3.3. | BC5: 1.3.4. | BD5: 2.1.1. | BE5: 2.1.2. | BF5: 2.1.3. | BG5: 2.1.4. | BH5: 2.1.5. | BI5: 2.2.1. | BJ5: 2.2.2. | BK5: 2.2.3. | BL5: 2.2.4. | BM5: 2.3.1. | BN5: 2.3.2. | BO5: 2.3.3. | BP5: 2.3.4. | BQ5: 3.1.1. | BR5: 3.1.2. | BS5: 3.1.3. | BT5: 3.1.4. | BU5: 3.2.1. | BV5: 3.2.2. | BW5: 3.2.3. | BX5: 3.2.4. | BY5: 3.2.5. | BZ5: 3.3.1. | CA5: 3.3.2. | CB5: 3.3.3. | CC5: 3.3.4. | CD5: 4.1.1. | CE5: 4.1.2. | CF5: 4.1.3. | CG5: 4.1.4. | CH5: 4.2.1. | CI5: 4.2.2. | CJ5: 4.2.3. | CK5: 4.2.4. | CL5: 4.3.1. | CM5: 4.3.2. | CN5: 4.3.3. | CO5: 4.3.4. | CP5: 4.3.5. | CQ5: 1.1.1. | CR5: 1.1.2. | CS5: 1.1.3. | CT5: 1.1.4. | CU5: 1.1.5. | CV5: 1.1.6. | CW5: 1.2.1. | CX5: 1.2.2. | CY5: 1.2.3. | CZ5: 1.2.4. | DA5: 1.3.1. | DB5: 1.3.2. | DC5: 1.3.3. | DD5: 1.3.4. | DE5: 2.1.1. | DF5: 2.1.2. | DG5: 2.1.3. | DH5: 2.1.4. | DI5: 2.1.5. | DJ5: 2.2.1. | DK5: 2.2.2. | DL5: 2.2.3. | DM5: 2.2.4. | DN5: 2.3.1. | DO5: 2.3.2. | DP5: 2.3.3. | DQ5: 2.3.4. | DR5: 3.1.1. | DS5: 3.1.2. | DT5: 3.1.3. | DU5: 3.1.4. | DV5: 3.2.1. | DW5: 3.2.2. | DX5: 3.2.3. | DY5: 3.2.4. | DZ5: 3.2.5. | EA5: 3.3.1. | EB5: 3.3.2. | EC5: 3.3.3. | ED5: 3.3.4. | EE5: 4.1.1. | EF5: 4.1.2. | EG5: 4.1.3. | EH5: 4.1.4. | EI5: 4.2.1. | EJ5: 4.2.2. | EK5: 4.2.3. | EL5: 4.2.4. | EM5: 4.3.1. | EN5: 4.3.2. | EO5: 4.3.3. | EP5: 4.3.4. | EQ5: 4.3.5.
A6: Economy | B6: ISO3Code | C6: region | D6: inc.group | E6: gdp.capita | F6: population | G6: NRI.score | H6: ISO2code | I6: NRI.ranking | J6: 1.score | K6: 2.score | L6: 3.score | M6: 4.score | N6: 1.ranking | O6: 2.ranking | P6: 3.ranking | Q6: 4.ranking | R6: 1.1.score | S6: 1.2.score | T6: 1.3.score | U6: 2.1.score | V6: 2.2.score | W6: 2.3.score | X6: 3.1.score | Y6: 3.2.score | Z6: 3.3.score | AA6: 4.1.score | AB6: 4.2.score | AC6: 4.3.score | AD6: 1.1.ranking | AE6: 1.2.ranking | AF6: 1.3.ranking | AG6: 2.1.ranking | AH6: 2.2.ranking | AI6: 2.3.ranking | AJ6: 3.1.ranking | AK6: 3.2.ranking | AL6: 3.3.ranking | AM6: 4.1.ranking | AN6: 4.2.ranking | AO6: 4.3.ranking | AP6: 1.1.1.score | AQ6: 1.1.2.score | AR6: 1.1.3.score | AS6: 1.1.4.score | AT6: 1.1.5.score | AU6: 1.1.6.score | AV6: 1.2.1.score | AW6: 1.2.2.score | AX6: 1.2.3.score | AY6: 1.2.4.score | AZ6: 1.3.1.score | BA6: 1.3.2.score | BB6: 1.3.3.score | BC6: 1.3.4.score | BD6: 2.1.1.score | BE6: 2.1.2.score | BF6: 2.1.3.score | BG6: 2.1.4.score | BH6: 2.1.5.score | BI6: 2.2.1.score | BJ6: 2.2.2.score | BK6: 2.2.3.score | BL6: 2.2.4.score | BM6: 2.3.1.score | BN6: 2.3.2.score | BO6: 2.3.3.score | BP6: 2.3.4.score | BQ6: 3.1.1.score | BR6: 3.1.2.score | BS6: 3.1.3.score | BT6: 3.1.4.score | BU6: 3.2.1.score | BV6: 3.2.2.score | BW6: 3.2.3.score | BX6: 3.2.4.score | BY6: 3.2.5.score | BZ6: 3.3.1.score | CA6: 3.3.2.score | CB6: 3.3.3.score | CC6: 3.3.4.score | CD6: 4.1.1.score | CE6: 4.1.2.score | CF6: 4.1.3.score | CG6: 4.1.4.score | CH6: 4.2.1.score | CI6: 4.2.2.score | CJ6: 4.2.3.score | CK6: 4.2.4.score | CL6: 4.3.1.score | CM6: 4.3.2.score | CN6: 4.3.3.score | CO6: 4.3.4.score | CP6: 4.3.5.score | CQ6: 1.1.1.rank | CR6: 1.1.2.rank | CS6: 1.1.3.rank | CT6: 1.1.4.rank | CU6: 1.1.5.rank | CV6: 1.1.6.rank | CW6: 1.2.1.rank | CX6: 1.2.2.rank | CY6: 1.2.3.rank | CZ6: 1.2.4.rank | DA6: 1.3.1.rank | DB6: 1.3.2.rank | DC6: 1.3.3.rank | DD6: 1.3.4.rank | DE6: 2.1.1.rank | DF6: 2.1.2.rank | DG6: 2.1.3.rank | DH6: 2.1.4.rank | DI6: 2.1.5.rank | DJ6: 2.2.1.rank | DK6: 2.2.2.rank | DL6: 2.2.3.rank | DM6: 2.2.4.rank | DN6: 2.3.1.rank | DO6: 2.3.2.rank | DP6: 2.3.3.rank | DQ6: 2.3.4.rank | DR6: 3.1.1.rank | DS6: 3.1.2.rank | DT6: 3.1.3.rank | DU6: 3.1.4.rank | DV6: 3.2.1.rank | DW6: 3.2.2.rank | DX6: 3.2.3.rank | DY6: 3.2.4.rank | DZ6: 3.2.5.rank | EA6: 3.3.1.rank | EB6: 3.3.2.rank | EC6: 3.3.3.rank | ED6: 3.3.4.rank | EE6: 4.1.1.rank | EF6: 4.1.2.rank | EG6: 4.1.3.rank | EH6: 4.1.4.rank | EI6: 4.2.1.rank | EJ6: 4.2.2.rank | EK6: 4.2.3.rank | EL6: 4.2.4.rank | EM6: 4.3.1.rank | EN6: 4.3.2.rank | EO6: 4.3.3.rank | EP6: 4.3.4.rank | EQ6: 4.3.5.rank
A7: United States of America | B7: USA | C7: The Americas | D7: High-income | E7: 89598.86 | F7: 343477000 | G7: 79.130951 | H7: US | I7: 1 | J7: 82.46917 | K7: 76.156544 | L7: 86.480215 | M7: 71.417873 | N7: 1 | O7: 1 | P7: 9 | Q7: 16 | R7: 87.233503 | S7: 76.143478 | T7: 84.030529 | U7: 67.071532 | V7: 84.060786 | W7: 77.337313 | X7: 94.729462 | Y7: 80.60483 | Z7: 84.106355 | AA7: 73.507594 | AB7: 63.247559 | AC7: 77.498468 | AD7: 2 | AE7: 1 | AF7: 1 | AG7: 14 | AH7: 1 | AI7: 2 | AJ7: 3 | AK7: 18 | AL7: 12 | AM7: 3 | AN7: 73 | AO7: 34 | AP7: 84.541446 | AQ7: 95.961898 | AR7: 58.483683 | AS7: 94.736842 | AT7: 89.67715 | AU7: 100 | AV7: 61.663406 | AW7: 68.932766 | AX7: 73.977738 | AY7: 100 | AZ7: 98.647926 | BA7: 100 | BB7: 37.47419 | BC7: 100 | BD7: 83.00324 | BE7: 80.518087 | BF7: 73.447061 | BG7: n/a | BH7: 31.317741 | BI7: n/a | BJ7: 58.063167 | BK7: 94.119192 | BL7: 100 | BM7: 89.603109 | BN7: 65.46443 | BO7: 100 | BP7: 54.281712 | BQ7: 98.17468 | BR7: 99.827535 | BS7: n/a | BT7: 86.18617 | BU7: 77.106013 | BV7: 74.6875 | BW7: 88.206996 | BX7: 100 | BY7: 63.023642 | BZ7: 94.202285 | CA7: 88.495713 | CB7: 69.621065 | CC7: n/a | CD7: 100 | CE7: 97.720334 | CF7: 81.235777 | CG7: 15.074263 | CH7: 77.390527 | CI7: 52.083333 | CJ7: 54.081633 | CK7: 66.455998 | CL7: 100 | CM7: 62.904905 | CN7: 87.272727 | CO7: 69.106566 | CP7: 81.419344 | CQ7: 28 | CR7: 17 | CS7: 13 | CT7: 63 | CU7: 6 | CV7: 1 | CW7: 16 | CX7: 8 | CY7: 19 | CZ7: 1 | DA7: 4 | DB7: 1 | DC7: 10 | DD7: 1 | DE7: 3 | DF7: 12 | DG7: 55 | DH7: n/a | DI7: 25 | DJ7: n/a | DK7: 8 | DL7: 2 | DM7: 1 | DN7: 17 | DO7: 16 | DP7: 1 | DQ7: 4 | DR7: 5 | DS7: 13 | DT7: n/a | DU7: 8 | DV7: 18 | DW7: 61 | DX7: 6 | DY7: 1 | DZ7: 63 | EA7: 11 | EB7: 33 | EC7: 19 | ED7: n/a | EE7: 1 | EF7: 2 | EG7: 7 | EH7: 59 | EI7: 24 | EJ7: 103 | EK7: 87 | EL7: 63 | EM7: 1 | EN7: 17 | EO7: 37 | EP7: 83 | EQ7: 31
A8: Finland | B8: FIN | C8: Europe | D8: High-income | E8: 66512.47 | F8: 5601000 | G8: 75.823837 | H8: FI | I8: 2 | J8: 66.281468 | K8: 62.938287 | L8: 88.905536 | M8: 85.170059 | N8: 9 | O8: 10 | P8: 4 | Q8: 1 | R8: 79.372358 | S8: 56.236637 | T8: 63.235408 | U8: 66.167772 | V8: 55.461729 | W8: 67.185361 | X8: 92.813656 | Y8: 91.16848 | Z8: 82.734471 | AA8: 79.005205 | AB8: 95.205334 | AC8: 81.299637 | AD8: 22 | AE8: 10 | AF8: 10 | AG8: 17 | AH8: 18 | AI8: 10 | AJ8: 6 | AK8: 3 | AL8: 17 | AM8: 2 | AN8: 1 | AO8: 25 | AP8: 78.898928 | AQ8: 100 | AR8: 30.333542 | AS8: 99.947368 | AT8: 67.054312 | AU8: 100 | AV8: 98.817152 | AW8: 39.684846 | AX8: 79.282406 | AY8: 7.1621455 | AZ8: 96.072497 | BA8: 87.75 | BB8: 22.318795 | BC8: 46.800341 | BD8: 29.727528 | BE8: 100 | BF8: 83.431864 | BG8: n/a | BH8: 51.511694 | BI8: 100 | BJ8: 42.611544 | BK8: 46.290606 | BL8: 32.944767 | BM8: 89.139929 | BN8: 71.304038 | BO8: 59.588556 | BP8: 48.70892 | BQ8: 97.348226 | BR8: 100 | BS8: n/a | BT8: 81.092743 | BU8: 86.400571 | BV8: 98.125 | BW8: 94.564445 | BX8: 100 | BY8: 76.752385 | BZ8: 88.40457 | CA8: 95.394515 | CB8: 64.404327 | CC8: n/a | CD8: 100 | CE8: 55.856156 | CF8: 94.292965 | CG8: 65.871698 | CH8: 100 | CI8: 96.614583 | CJ8: 90.816327 | CK8: 87.186513 | CL8: 100 | CM8: 65.261074 | CN8: 96.363636 | CO8: 65.339074 | CP8: 96.469524 | CQ8: 39 | CR8: 1 | CS8: 68 | CT8: 25 | CU8: 89 | CV8: 1 | CW8: 3 | CX8: 21 | CY8: 9 | CZ8: 54 | DA8: 7 | DB8: 5 | DC8: 20 | DD8: 14 | DE8: 38 | DF8: 1 | DG8: 15 | DH8: n/a | DI8: 6 | DJ8: 1 | DK8: 13 | DL8: 47 | DM8: 22 | DN8: 19 | DO8: 7 | DP8: 29 | DQ8: 10 | DR8: 6 | DS8: 1 | DT8: n/a | DU8: 13 | DV8: 7 | DW8: 3 | DX8: 2 | DY8: 1 | DZ8: 35 | EA8: 19 | EB8: 20 | EC8: 58 | ED8: n/a | EE8: 1 | EF8: 59 | EG8: 3 | EH8: 7 | EI8: 1 | EJ8: 4 | EK8: 14 | EL8: 20 | EM8: 1 | EN8: 11 | EO8: 15 | EP8: 90 | EQ8: 5
A9: Singapore | B9: SGP | C9: Asia & Pacific | D9: High-income | E9: 156969.07 | F9: 5789000 | G9: 75.462405 | H9: SG | I9: 3 | J9: 70.422542 | K9: 68.104724 | L9: 84.408291 | M9: 78.914062 | N9: 4 | O9: 4 | P9: 15 | Q9: 7 | R9: 85.695613 | S9: 52.548694 | T9: 73.023318 | U9: 74.433802 | V9: 56.800785 | W9: 73.079586 | X9: 88.566838 | Y9: 80.274911 | Z9: 84.383123 | AA9: 68.197574 | AB9: 81.410299 | AC9: 87.134313 | AD9: 4 | AE9: 14 | AF9: 2 | AG9: 3 | AH9: 14 | AI9: 4 | AJ9: 12 | AK9: 19 | AL9: 9 | AM9: 6 | AN9: 17 | AO9: 4 | AP9: 96.73774 | AQ9: 100 | AR9: 24.482816 | AS9: 100 | AT9: 92.953119 | AU9: 100 | AV9: 100 | AW9: 20.259801 | AX9: 84.518629 | AY9: 5.416346 | AZ9: 97.378329 | BA9: 78.5 | BB9: 100 | BC9: 16.214943 | BD9: 12.663184 | BE9: 90.376798 | BF9: 91.658317 | BG9: 96.923077 | BH9: 80.547633 | BI9: 61.383446 | BJ9: 83.572407 | BK9: 45.180098 | BL9: 37.067188 | BM9: 97.962007 | BN9: n/a | BO9: 92.241239 | BP9: 29.035511 | BQ9: 98.694832 | BR9: 99.827535 | BS9: n/a | BT9: 67.178148 | BU9: 100 | BV9: 87.8125 | BW9: 93.767363 | BX9: 75 | BY9: 44.794691 | BZ9: 95.651714 | CA9: 91.834174 | CB9: 65.66348 | CC9: n/a | CD9: 98.306305 | CE9: 64.392816 | CF9: 85.963445 | CG9: 24.127729 | CH9: 73.838248 | CI9: 79.6875 | CJ9: n/a | CK9: 100 | CL9: 100 | CM9: 91.937508 | CN9: 74.545455 | CO9: 86.8676 | CP9: 90.373384 | CQ9: 4 | CR9: 1 | CS9: 84 | CT9: 1 | CU9: 4 | CV9: 1 | CW9: 1 | CX9: 34 | CY9: 3 | CZ9: 65 | DA9: 5 | DB9: 13 | DC9: 1 | DD9: 69 | DE9: 71 | DF9: 2 | DG9: 4 | DH9: 28 | DI9: 2 | DJ9: 51 | DK9: 5 | DL9: 50 | DM9: 18 | DN9: 6 | DO9: n/a | DP9: 3 | DQ9: 19 | DR9: 3 | DS9: 13 | DT9: n/a | DU9: 23 | DV9: 1 | DW9: 25 | DX9: 3 | DY9: 72 | DZ9: 95 | EA9: 7 | EB9: 26 | EC9: 52 | ED9: n/a | EE9: 6 | EF9: 34 | EG9: 4 | EH9: 41 | EI9: 31 | EJ9: 49 | EK9: n/a | EL9: 1 | EM9: 1 | EN9: 2 | EO9: 72 | EP9: 22 | EQ9: 18
A10: Denmark | B10: DNK | C10: Europe | D10: High-income | E10: 84762.884 | F10: 5948000 | G10: 75.135904 | H10: DK | I10: 4 | J10: 67.473821 | K10: 58.748614 | L10: 92.023059 | M10: 82.298123 | N10: 8 | O10: 17 | P10: 1 | Q10: 3 | R10: 80.432016 | S10: 57.897621 | T10: 64.091826 | U10: 53.686631 | V10: 58.585059 | W10: 63.974153 | X10: 99.977835 | Y10: 87.456211 | Z10: 88.63513 | AA10: 67.597527 | AB10: 91.269017 | AC10: 88.027825 | AD10: 16 | AE10: 8 | AF10: 9 | AG10: 54 | AH10: 11 | AI10: 18 | AJ10: 1 | AK10: 8 | AL10: 2 | AM10: 7 | AN10: 4 | AO10: 2 | AP10: 92.422848 | AQ10: 93.036021 | AR10: 29.120567 | AS10: 100 | AT10: 68.012658 | AU10: 100 | AV10: 74.284614 | AW10: 79.588897 | AX10: 73.517309 | AY10: 4.1996652 | AZ10: 90.636248 | BA10: 76.75 | BB10: 40.164264 | BC10: 48.816793 | BD10: 20.896896 | BE10: 78.932749 | BF10: 83.25687 | BG10: n/a | BH10: 31.660011 | BI10: 92.248862 | BJ10: 54.912272 | BK10: 51.505422 | BL10: 35.673681 | BM10: 99.908567 | BN10: 69.284186 | BO10: 39.698501 | BP10: 47.005355 | BQ10: 100 | BR10: 100 | BS10: n/a | BT10: 99.933505 | BU10: 88.261664 | BV10: 94.375 | BW10: 77.746838 | BX10: 100 | BY10: 76.897553 | BZ10: 98.550571 | CA10: 99.078964 | CB10: 68.275856 | CC10: n/a | CD10: 86.253361 | CE10: 58.916077 | CF10: 100 | CG10: 25.220671 | CH10: 95.196604 | CI10: 92.578125 | CJ10: 84.438776 | CK10: 87.625868 | CL10: 100 | CM10: 63.408659 | CN10: 100 | CO10: 92.787944 | CP10: 91.829397 | CQ10: 9 | CR10: 23 | CS10: 73 | CT10: 1 | CU10: 84 | CV10: 1 | CW10: 9 | CX10: 6 | CY10: 21 | CZ10: 69 | DA10: 11 | DB10: 14 | DC10: 8 | DD10: 8 | DE10: 48 | DF10: 15 | DG10: 17 | DH10: n/a | DI10: 23 | DJ10: 11 | DK10: 9 | DL10: 28 | DM10: 20 | DN10: 2 | DO10: 12 | DP10: 55 | DQ10: 11 | DR10: 1 | DS10: 1 | DT10: n/a | DU10: 2 | DV10: 5 | DW10: 5 | DX10: 17 | DY10: 1 | DZ10: 34 | EA10: 2 | EB10: 6 | EC10: 29 | ED10: n/a | EE10: 10 | EF10: 51 | EG10: 1 | EH10: 39 | EI10: 2 | EJ10: 11 | EK10: 23 | EL10: 16 | EM10: 1 | EN10: 16 | EO10: 1 | EP10: 8 | EQ10: 15
A11: Sweden | B11: SWE | C11: Europe | D11: High-income | E11: 73069.51 | F11: 10551000 | G11: 75.086618 | H11: SE | I11: 5 | J11: 69.043628 | K11: 62.360027 | L11: 86.679974 | M11: 82.262845 | N11: 6 | O11: 11 | P11: 8 | Q11: 4 | R11: 79.816405 | S11: 57.278724 | T11: 70.035756 | U11: 58.508155 | V11: 58.451885 | W11: 70.120039 | X11: 92.551596 | Y11: 87.972395 | Z11: 79.51593 | AA11: 71.162056 | AB11: 90.692968 | AC11: 84.933509 | AD11: 19 | AE11: 9 | AF11: 3 | AG11: 34 | AH11: 12 | AI11: 6 | AJ11: 7 | AK11: 5 | AL11: 24 | AM11: 5 | AN11: 5 | AO11: 10 | AP11: 86.457628 | AQ11: 83.911159 | AR11: 39.049143 | AS11: 100 | AT11: 69.480497 | AU11: 100 | AV11: 85.139554 | AW11: 57.316392 | AX11: 78.370324 | AY11: 8.2886252 | AZ11: 88.502538 | BA11: 92 | BB11: 45.98188 | BC11: 53.658605 | BD11: 26.062296 | BE11: 85.208413 | BF11: 84.655809 | BG11: n/a | BH11: 38.106104 | BI11: 92.643535 | BJ11: 50.254737 | BK11: 50.798079 | BL11: 40.111189 | BM11: 85.997522 | BN11: 58.110725 | BO11: 79.645581 | BP11: 56.726329 | BQ11: 87.929554 | BR11: 99.174284 | BS11: n/a | BT11: 90.550951 | BU11: 85.221104 | BV11: 81.25 | BW11: 79.404972 | BX11: 100 | BY11: 93.985898 | BZ11: 78.25857 | CA11: 96.188741 | CB11: 64.100479 | CC11: n/a | CD11: 100 | CE11: 63.036348 | CF11: 69.550273 | CG11: 52.061602 | CH11: 91.264522 | CI11: 92.1875 | CJ11: 85.969388 | CK11: 91.284378 | CL11: 100 | CM11: 62.08404 | CN11: 100 | CO11: 78.794403 | CP11: 97.711191 | CQ11: 18 | CR11: 40 | CS11: 44 | CT11: 1 | CU11: 74 | CV11: 1 | CW11: 5 | CX11: 14 | CY11: 11 | CZ11: 50 | DA11: 13 | DB11: 3 | DC11: 6 | DD11: 4 | DE11: 41 | DF11: 6 | DG11: 11 | DH11: n/a | DI11: 15 | DJ11: 8 | DK11: 11 | DL11: 30 | DM11: 15 | DN11: 27 | DO11: 19 | DP11: 11 | DQ11: 3 | DR11: 19 | DS11: 18 | DT11: n/a | DU11: 3 | DV11: 10 | DW11: 41 | DX11: 15 | DY11: 1 | DZ11: 7 | EA11: 35 | EB11: 14 | EC11: 63 | ED11: n/a | EE11: 1 | EF11: 40 | EG11: 23 | EH11: 12 | EI11: 4 | EJ11: 13 | EK11: 19 | EL11: 8 | EM11: 1 | EN11: 18 | EO11: 1 | EP11: 50 | EQ11: 3
A12: Netherlands | B12: NLD | C12: Europe | D12: High-income | E12: 84035.223 | F12: 18093000 | G12: 75.084632 | H12: NL | I12: 6 | J12: 72.01495 | K12: 58.711721 | L12: 89.564062 | M12: 80.047793 | N12: 3 | O12: 18 | P12: 3 | Q12: 5 | R12: 80.84258 | S12: 69.61211 | T12: 65.59016 | U12: 55.556759 | V12: 57.604596 | W12: 62.973808 | X12: 94.835416 | Y12: 89.67707 | Z12: 84.179702 | AA12: 67.458627 | AB12: 87.279674 | AC12: 85.405078 | AD12: 15 | AE12: 3 | AF12: 7 | AG12: 45 | AH12: 13 | AI12: 19 | AJ12: 2 | AK12: 4 | AL12: 11 | AM12: 8 | AN12: 7 | AO12: 8 | AP12: 86.162742 | AQ12: 94.006383 | AR12: 34.956122 | AS12: 94.736842 | AT12: 75.193391 | AU12: 100 | AV12: 93.595754 | AW12: 100 | AX12: 72.130879 | AY12: 12.721806 | AZ12: 96.373878 | BA12: 87.75 | BB12: 35.791563 | BC12: 42.445197 | BD12: 20.55566 | BE12: 67.541494 | BF12: 86.154981 | BG12: n/a | BH12: 47.9749 | BI12: 88.698512 | BJ12: 35.621531 | BK12: 59.404439 | BL12: 46.693903 | BM12: 90.517438 | BN12: 73.285472 | BO12: 53.047656 | BP12: 35.044667 | BQ12: 98.261094 | BR12: 99.059948 | BS12: n/a | BT12: 87.185206 | BU12: 87.046632 | BV12: 89.6875 | BW12: 81.356734 | BX12: 100 | BY12: 90.294484 | BZ12: 92.752857 | CA12: 95.953965 | CB12: 63.832283 | CC12: n/a | CD12: 72.473749 | CE12: 69.2295 | CF12: 94.324526 | CG12: 33.806731 | CH12: 90.393208 | CI12: 80.208333 | CJ12: 95.153061 | CK12: 87.3219 | CL12: 100 | CM12: 59.040855 | CN12: 100 | CO12: 87.082885 | CP12: 90.99314 | CQ12: 23 | CR12: 22 | CS12: 54 | CT12: 63 | CU12: 44 | CV12: 1 | CW12: 4 | CX12: 1 | CY12: 27 | CZ12: 44 | DA12: 6 | DB12: 5 | DC12: 12 | DD12: 20 | DE12: 49 | DF12: 34 | DG12: 9 | DH12: n/a | DI12: 9 | DJ12: 14 | DK12: 17 | DL12: 17 | DM12: 10 | DN12: 15 | DO12: 5 | DP12: 32 | DQ12: 15 | DR12: 4 | DS12: 22 | DT12: n/a | DU12: 7 | DV12: 6 | DW12: 19 | DX12: 12 | DY12: 1 | DZ12: 12 | EA12: 12 | EB12: 16 | EC12: 65 | ED12: n/a | EE12: 11 | EF12: 27 | EG12: 2 | EH12: 26 | EI12: 5 | EJ12: 45 | EK12: 5 | EL12: 19 | EM12: 1 | EN12: 25 | EO12: 1 | EP12: 21 | EQ12: 17
A13: Germany | B13: DEU | C13: Europe | D13: High-income | E13: 73553.296 | F13: 84548000 | G13: 74.121352 | H13: DE | I13: 7 | J13: 70.274689 | K13: 63.049616 | L13: 86.835444 | M13: 76.325659 | N13: 5 | O13: 9 | P13: 6 | Q13: 9 | R13: 81.550008 | S13: 64.953371 | T13: 64.320689 | U13: 58.722097 | V13: 62.339869 | W13: 68.08688 | X13: 87.379837 | Y13: 85.512986 | Z13: 87.61351 | AA13: 64.566047 | AB13: 79.631509 | AC13: 84.779422 | AD13: 13 | AE13: 4 | AF13: 8 | AG13: 32 | AH13: 8 | AI13: 8 | AJ13: 16 | AK13: 14 | AL13: 5 | AM13: 9 | AN13: 22 | AO13: 12 | AP13: 90.40681 | AQ13: 97.813044 | AR13: 40.944455 | AS13: 99.842105 | AT13: 78.743623 | AU13: n/a | AV13: 60.656541 | AW13: 78.476659 | AX13: 69.3514 | AY13: 51.328885 | AZ13: 78.213017 | BA13: 86.75 | BB13: 54.779189 | BC13: 37.540549 | BD13: 40.321764 | BE13: 60.899431 | BF13: 84.665483 | BG13: n/a | BH13: 49.001711 | BI13: 93.835852 | BJ13: 17.314972 | BK13: 72.945954 | BL13: 65.2627 | BM13: 90.837454 | BN13: 71.150594 | BO13: 61.470294 | BP13: 48.889179 | BQ13: 96.110652 | BR13: 97.421985 | BS13: n/a | BT13: 68.606875 | BU13: 78.688625 | BV13: 89.6875 | BW13: 74.327754 | BX13: 100 | BY13: 84.861054 | BZ13: 97.101143 | CA13: 99.885735 | CB13: 65.853651 | CC13: n/a | CD13: 88.758458 | CE13: 82.710986 | CF13: 69.040548 | CG13: 17.754196 | CH13: 78.038427 | CI13: 79.947917 | CJ13: 78.061224 | CK13: 83.75514 | CL13: 100 | CM13: 59.980755 | CN13: 100 | CO13: 86.437029 | CP13: 85.399809 | CQ13: 10 | CR13: 9 | CS13: 41 | CT13: 28 | CU13: 27 | CV13: n/a | CW13: 17 | CX13: 7 | CY13: 44 | CZ13: 16 | DA13: 25 | DB13: 7 | DC13: 4 | DD13: 21 | DE13: 22 | DF13: 41 | DG13: 10 | DH13: n/a | DI13: 8 | DJ13: 4 | DK13: 34 | DL13: 5 | DM13: 3 | DN13: 12 | DO13: 9 | DP13: 26 | DQ13: 9 | DR13: 9 | DS13: 33 | DT13: n/a | DU13: 22 | DV13: 16 | DW13: 19 | DX13: 21 | DY13: 1 | DZ13: 21 | EA13: 4 | EB13: 2 | EC13: 50 | ED13: n/a | EE13: 9 | EF13: 6 | EG13: 24 | EH13: 52 | EI13: 22 | EJ13: 46 | EK13: 37 | EL13: 26 | EM13: 1 | EN13: 23 | EO13: 1 | EP13: 24 | EQ13: 26
A14: United Kingdom | B14: GBR | C14: Europe | D14: High-income | E14: 63759.051 | F14: 68683000 | G14: 73.851632 | H14: GB | I14: 8 | J14: 67.741272 | K14: 67.973041 | L14: 84.618739 | M14: 75.073475 | N14: 7 | O14: 5 | P14: 13 | Q14: 11 | R14: 83.053023 | S14: 64.277772 | T14: 55.893022 | U14: 58.706111 | V14: 71.552575 | W14: 73.660437 | X14: 87.948118 | Y14: 78.32928 | Z14: 87.57882 | AA14: 58.294252 | AB14: 79.882022 | AC14: 87.044151 | AD14: 11 | AE14: 5 | AF14: 17 | AG14: 33 | AH14: 3 | AI14: 3 | AJ14: 14 | AK14: 24 | AL14: 6 | AM14: 13 | AN14: 20 | AO14: 6 | AP14: 81.871537 | AQ14: 100 | AR14: 45.011122 | AS14: 99.473684 | AT14: 88.90877 | AU14: n/a | AV14: 55.610855 | AW14: 68.223533 | AX14: 72.937412 | AY14: 60.339289 | AZ14: 84.700879 | BA14: 82.25 | BB14: 12.603992 | BC14: 44.017215 | BD14: 42.255254 | BE14: 72.004103 | BF14: 84.227378 | BG14: n/a | BH14: 36.337707 | BI14: 83.084314 | BJ14: 70.071615 | BK14: 69.977142 | BL14: 63.07723 | BM14: 94.404543 | BN14: 71.310211 | BO14: 84.878502 | BP14: 44.048492 | BQ14: 89.677605 | BR14: 100 | BS14: n/a | BT14: 74.166747 | BU14: 80.680378 | BV14: 91.5625 | BW14: 66.54164 | BX14: 100 | BY14: 52.861883 | BZ14: 97.101143 | CA14: 99.335176 | CB14: 66.300141 | CC14: n/a | CD14: 40.828798 | CE14: 79.474574 | CF14: 79.462626 | CG14: 33.411011 | CH14: 77.479893 | CI14: 81.770833 | CJ14: 78.061224 | CK14: 82.729457 | CL14: 100 | CM14: 64.948432 | CN14: 96.363636 | CO14: 90.958019 | CP14: 91.813035 | CQ14: 34 | CR14: 1 | CS14: 32 | CT14: 29 | CU14: 7 | CV14: n/a | CW14: 20 | CX14: 10 | CY14: 25 | CZ14: 11 | DA14: 16 | DB14: 8 | DC14: 24 | DD14: 17 | DE14: 20 | DF14: 28 | DG14: 12 | DH14: n/a | DI14: 18 | DJ14: 22 | DK14: 7 | DL14: 7 | DM14: 4 | DN14: 7 | DO14: 6 | DP14: 7 | DQ14: 12 | DR14: 16 | DS14: 1 | DT14: n/a | DU14: 18 | DV14: 14 | DW14: 13 | DX14: 29 | DY14: 1 | DZ14: 84 | EA14: 4 | EB14: 5 | EC14: 45 | ED14: n/a | EE14: 20 | EF14: 10 | EG14: 10 | EH14: 27 | EI14: 23 | EJ14: 39 | EK14: 37 | EL14: 27 | EM14: 1 | EN14: 13 | EO14: 15 | EP14: 11 | EQ14: 16
A15: Switzerland | B15: CHE | C15: Europe | D15: High-income | E15: 97659.278 | F15: 8871000 | G15: 73.62597 | H15: CH | I15: 9 | J15: 73.595801 | K15: 59.490276 | L15: 83.761682 | M15: 77.656119 | N15: 2 | O15: 15 | P15: 17 | Q15: 8 | R15: 81.215336 | S15: 70.518444 | T15: 69.053624 | U15: 60.167528 | V15: 51.485538 | W15: 66.817762 | X15: 81.482312 | Y15: 87.872716 | Z15: 81.930019 | AA15: 64.27619 | AB15: 83.009722 | AC15: 85.682445 | AD15: 14 | AE15: 2 | AF15: 5 | AG15: 25 | AH15: 22 | AI15: 12 | AJ15: 30 | AK15: 6 | AL15: 19 | AM15: 10 | AN15: 13 | AO15: 7 | AP15: 94.535941 | AQ15: 96.152722 | AR15: 27.122856 | AS15: 100 | AT15: 69.480497 | AU15: 100 | AV15: 100 | AW15: 100 | AX15: 74.658435 | AY15: 7.415339 | AZ15: 99.624769 | BA15: 89.25 | BB15: 35.852803 | BC15: 51.486924 | BD15: 20.345277 | BE15: 86.077748 | BF15: 81.081086 | BG15: n/a | BH15: 53.166001 | BI15: n/a | BJ15: 53.220826 | BK15: 57.132374 | BL15: 44.103415 | BM15: 80.847199 | BN15: n/a | BO15: 67.665237 | BP15: 51.940851 | BQ15: 96.853928 | BR15: 89.492691 | BS15: n/a | BT15: 58.100318 | BU15: 85.505457 | BV15: 91.5625 | BW15: 89.576835 | BX15: 75 | BY15: 97.718789 | BZ15: 81.157427 | CA15: 100 | CB15: 64.63263 | CC15: n/a | CD15: 90.913043 | CE15: 64.074279 | CF15: 79.461048 | CG15: 22.656391 | CH15: 82.104558 | CI15: 83.984375 | CJ15: 74.489796 | CK15: 91.390673 | CL15: 100 | CM15: 66.438021 | CN15: 82.727273 | CO15: 95.47901 | CP15: 96.170954 | CQ15: 6 | CR15: 15 | CS15: 78 | CT15: 1 | CU15: 74 | CV15: 1 | CW15: 1 | CX15: 1 | CY15: 16 | CZ15: 52 | DA15: 2 | DB15: 4 | DC15: 11 | DD15: 6 | DE15: 52 | DF15: 5 | DG15: 25 | DH15: n/a | DI15: 5 | DJ15: n/a | DK15: 10 | DL15: 20 | DM15: 13 | DN15: 38 | DO15: n/a | DP15: 20 | DQ15: 7 | DR15: 7 | DS15: 63 | DT15: n/a | DU15: 38 | DV15: 9 | DW15: 13 | DX15: 5 | DY15: 72 | DZ15: 4 | EA15: 32 | EB15: 1 | EC15: 57 | ED15: n/a | EE15: 8 | EF15: 36 | EG15: 11 | EH15: 44 | EI15: 13 | EJ15: 33 | EK15: 48 | EL15: 7 | EM15: 1 | EN15: 9 | EO15: 51 | EP15: 4 | EQ15: 6
A16: Republic of Korea | B16: KOR | C16: Asia & Pacific | D16: High-income | E16: 65080.293 | F16: 51749000 | G16: 72.377478 | H16: KR | I16: 10 | J16: 66.070532 | K16: 72.554143 | L16: 82.045568 | M16: 68.839667 | N16: 10 | O16: 2 | P16: 20 | Q16: 22 | R16: 78.426782 | S16: 49.805448 | T16: 69.979368 | U16: 74.311554 | V16: 60.497275 | W16: 82.853601 | X16: 88.497555 | Y16: 71.440574 | Z16: 86.198576 | AA16: 59.474208 | AB16: 68.301939 | AC16: 78.742854 | AD16: 29 | AE16: 17 | AF16: 4 | AG16: 4 | AH16: 10 | AI16: 1 | AJ16: 13 | AK16: 38 | AL16: 7 | AM16: 12 | AN16: 56 | AO16: 31 | AP16: 65.376364 | AQ16: 67.924801 | AR16: 58.281703 | AS16: 99.473684 | AT16: 79.504138 | AU16: 100 | AV16: 57.036315 | AW16: 8.6966176 | AX16: 74.744798 | AY16: 58.744062 | AZ16: 100 | BA16: 59.5 | BB16: 100 | BC16: 20.417471 | BD16: 45.406593 | BE16: 81.714695 | BF16: 98.53453 | BG16: 98.155231 | BH16: 47.74672 | BI16: 69.135948 | BJ16: 74.451266 | BK16: 61.197162 | BL16: 37.204722 | BM16: 100 | BN16: 86.129231 | BO16: 67.159569 | BP16: 78.125605 | BQ16: 75.581933 | BR16: 100 | BS16: n/a | BT16: 89.910732 | BU16: 70.319096 | BV16: 55.9375 | BW16: 64.376384 | BX16: 100 | BY16: 66.569888 | BZ16: 97.101143 | CA16: 92.497878 | CB16: 68.996709 | CC16: n/a | CD16: 100 | CE16: 76.874065 | CF16: 47.878247 | CG16: 13.144521 | CH16: 62.064343 | CI16: 56.510417 | CJ16: 76.785714 | CK16: 95.8764 | CL16: 100 | CM16: 77.020409 | CN16: 82.727273 | CO16: 63.832078 | CP16: 82.783311 | CQ16: 67 | CR16: 59 | CS16: 14 | CT16: 29 | CU16: 25 | CV16: 1 | CW16: 19 | CX16: 48 | CY16: 15 | CZ16: 12 | DA16: 1 | DB16: 34 | DC16: 1 | DD16: 51 | DE16: 16 | DF16: 10 | DG16: 3 | DH16: 22 | DI16: 10 | DJ16: 38 | DK16: 6 | DL16: 14 | DM16: 17 | DN16: 1 | DO16: 2 | DP16: 21 | DQ16: 2 | DR16: 44 | DS16: 1 | DT16: n/a | DU16: 4 | DV16: 26 | DW16: 85 | DX16: 32 | DY16: 1 | DZ16: 55 | EA16: 4 | EB16: 25 | EC16: 23 | ED16: n/a | EE16: 1 | EF16: 14 | EG16: 51 | EH16: 64 | EI16: 56 | EJ16: 95 | EK16: 40 | EL16: 3 | EM16: 1 | EN16: 4 | EO16: 51 | EP16: 93 | EQ16: 29
A17: Japan | B17: JPN | C17: Asia & Pacific | D17: High-income | E17: 54815.317 | F17: 124371000 | G17: 70.21505 | H17: JP | I17: 11 | J17: 61.280022 | K17: 66.869788 | L17: 80.57883 | M17: 72.131561 | N17: 16 | O17: 8 | P17: 24 | Q17: 15 | R17: 83.203018 | S17: 37.757632 | T17: 62.879416 | U17: 72.681001 | V17: 61.777499 | W17: 66.150864 | X17: 80.392665 | Y17: 78.061123 | Z17: 83.2827 | AA17: 63.153139 | AB17: 72.862803 | AC17: 80.37874 | AD17: 10 | AE17: 41 | AF17: 11 | AG17: 6 | AH17: 9 | AI17: 15 | AJ17: 33 | AK17: 25 | AL17: 15 | AM17: 11 | AN17: 42 | AO17: 26 | AP17: 76.767733 | AQ17: 96.34768 | AR17: 66.023586 | AS17: 99.473684 | AT17: 77.402406 | AU17: n/a | AV17: 25.631816 | AW17: 12.703454 | AX17: 70.841509 | AY17: 41.853749 | AZ17: 91.42559 | BA17: 80 | BB17: 54.451485 | BC17: 25.640588 | BD17: 58.074245 | BE17: 79.504381 | BF17: 80.464375 | BG17: n/a | BH17: n/a | BI17: n/a | BJ17: 47.685911 | BK17: 76.502607 | BL17: 61.14398 | BM17: 93.111247 | BN17: n/a | BO17: 51.1529 | BP17: 54.188444 | BQ17: 83.782486 | BR17: 97.084106 | BS17: n/a | BT17: 60.311403 | BU17: 78.997702 | BV17: 52.1875 | BW17: 72.82842 | BX17: 100 | BY17: 86.291995 | BZ17: 98.550571 | CA17: 95.631653 | CB17: 55.665876 | CC17: n/a | CD17: 100 | CE17: 83.5502 | CF17: 60.772258 | CG17: 8.2900989 | CH17: 64.499553 | CI17: 65.364583 | CJ17: 78.316327 | CK17: 99.132217 | CL17: 100 | CM17: 80.818748 | CN17: 69.090909 | CO17: 78.256189 | CP17: 86.698226 | CQ17: 45 | CR17: 13 | CS17: 8 | CT17: 29 | CU17: 31 | CV17: n/a | CW17: 38 | CX17: 41 | CY17: 32 | CZ17: 18 | DA17: 10 | DB17: 9 | DC17: 5 | DD17: 36 | DE17: 7 | DF17: 14 | DG17: 27 | DH17: n/a | DI17: n/a | DJ17: n/a | DK17: 12 | DL17: 4 | DM17: 5 | DN17: 9 | DO17: n/a | DP17: 34 | DQ17: 5 | DR17: 29 | DS17: 34 | DT17: n/a | DU17: 33 | DV17: 15 | DW17: 94 | DX17: 26 | DY17: 1 | DZ17: 19 | EA17: 2 | EB17: 19 | EC17: 84 | ED17: n/a | EE17: 1 | EF17: 5 | EG17: 35 | EH17: 80 | EI17: 53 | EJ17: 79 | EK17: 36 | EL17: 2 | EM17: 1 | EN17: 3 | EO17: 91 | EP17: 54 | EQ17: 22
A18: Canada | B18: CAN | C18: The Americas | D18: High-income | E18: 65500.245 | F18: 39299000 | G18: 70.10526 | H18: CA | I18: 12 | J18: 65.571027 | K18: 61.370767 | L18: 82.960557 | M18: 70.51869 | N18: 11 | O18: 12 | P18: 18 | Q18: 19 | R18: 77.864503 | S18: 59.893971 | T18: 58.954606 | U18: 56.499143 | V18: 62.553294 | W18: 65.059865 | X18: 85.946602 | Y18: 78.577344 | Z18: 84.357725 | AA18: 53.225127 | AB18: 79.091585 | AC18: 79.239359 | AD18: 30 | AE18: 7 | AF18: 14 | AG18: 40 | AH18: 7 | AI18: 16 | AJ18: 18 | AK18: 23 | AL18: 10 | AM18: 18 | AN18: 24 | AO18: 28 | AP18: 75.557289 | AQ18: 94.685057 | AR18: 44.031639 | AS18: 98.421053 | AT18: 76.627479 | AU18: n/a | AV18: 69.56653 | AW18: 61.66948 | AX18: 69.682584 | AY18: 38.657289 | AZ18: 88.540728 | BA18: 68.25 | BB18: 29.367002 | BC18: 49.660694 | BD18: 25.263579 | BE18: 76.833061 | BF18: 83.968384 | BG18: n/a | BH18: 39.931546 | BI18: 92.870881 | BJ18: 34.923435 | BK18: 68.141081 | BL18: 54.277778 | BM18: 82.574801 | BN18: 70.116231 | BO18: 79.390744 | BP18: 28.157684 | BQ18: 85.29172 | BR18: 91.803402 | BS18: n/a | BT18: 80.744684 | BU18: 83.386633 | BV18: 76.5625 | BW18: 79.05953 | BX18: 100 | BY18: 53.878059 | BZ18: 91.303428 | CA18: 95.813159 | CB18: 65.956589 | CC18: n/a | CD18: 48.468305 | CE18: 74.659727 | CF18: 72.916673 | CG18: 16.855802 | CH18: 79.155496 | CI18: 74.088542 | CJ18: 81.377551 | CK18: 86.683885 | CL18: 100 | CM18: 69.922294 | CN18: 100 | CO18: 48.977395 | CP18: 96.115497 | CQ18: 49 | CR18: 20 | CS18: 34 | CT18: 48 | CU18: 37 | CV18: n/a | CW18: 11 | CX18: 12 | CY18: 42 | CZ18: 20 | DA18: 12 | DB18: 20 | DC18: 14 | DD18: 7 | DE18: 42 | DF18: 19 | DG18: 13 | DH18: n/a | DI18: 13 | DJ18: 7 | DK18: 19 | DL18: 8 | DM18: 7 | DN18: 34 | DO18: 10 | DP18: 12 | DQ18: 22 | DR18: 26 | DS18: 55 | DT18: n/a | DU18: 14 | DV18: 11 | DW18: 54 | DX18: 16 | DY18: 1 | DZ18: 82 | EA18: 15 | EB18: 17 | EC18: 49 | ED18: n/a | EE18: 15 | EF18: 16 | EG18: 19 | EH18: 54 | EI18: 18 | EJ18: 59 | EK18: 29 | EL18: 23 | EM18: 1 | EN18: 7 | EO18: 1 | EP18: 110 | EQ18: 7
A19: Estonia | B19: EST | C19: Europe | D19: High-income | E19: 49087.453 | F19: 1367000 | G19: 69.947892 | H19: EE | I19: 13 | J19: 54.15136 | K19: 66.909067 | L19: 88.053136 | M19: 70.678007 | N19: 32 | O19: 7 | P19: 5 | Q19: 17 | R19: 76.656223 | S19: 48.103461 | T19: 37.694395 | U19: 62.614978 | V19: 70.204352 | W19: 67.907873 | X19: 89.428773 | Y19: 86.896617 | Z19: 87.834017 | AA19: 50.652158 | AB19: 78.501664 | AC19: 82.880199 | AD19: 37 | AE19: 18 | AF19: 52 | AG19: 21 | AH19: 4 | AI19: 9 | AJ19: 10 | AK19: 10 | AL19: 3 | AM19: 21 | AN19: 25 | AO19: 19 | AP19: 90.136042 | AQ19: 90.567371 | AR19: 17.868109 | AS19: 100 | AT19: 61.365817 | AU19: 100 | AV19: 69.613876 | AW19: 37.656574 | AX19: 83.459747 | AY19: 1.6836445 | AZ19: 76.827699 | BA19: 58.75 | BB19: 6.1255307 | BC19: 9.0743527 | BD19: 12.176424 | BE19: 67.530013 | BF19: 80.108916 | BG19: 99.808308 | BH19: 53.451226 | BI19: 76.215847 | BJ19: 100 | BK19: 34.397209 | BL19: n/a | BM19: 99.440575 | BN19: 100 | BO19: 43.276483 | BP19: 28.914434 | BQ19: 95.387273 | BR19: 94.037136 | BS19: n/a | BT19: 78.861909 | BU19: 78.004665 | BV19: 82.1875 | BW19: 81.487104 | BX19: 100 | BY19: 92.803816 | BZ19: 95.651714 | CA19: 97.162476 | CB19: 70.687862 | CC19: n/a | CD19: 10.768904 | CE19: 39.029899 | CF19: 83.66384 | CG19: 69.145987 | CH19: 70.531725 | CI19: 85.677083 | CJ19: 82.397959 | CK19: 76.194409 | CL19: 97.777778 | CM19: 73.743197 | CN19: 96.363636 | CO19: 73.412271 | CP19: 78.225606 | CQ19: 11 | CR19: 28 | CS19: 99 | CT19: 1 | CU19: 112 | CV19: 1 | CW19: 10 | CX19: 24 | CY19: 5 | CZ19: 87 | DA19: 30 | DB19: 35 | DC19: 36 | DD19: 85 | DE19: 72 | DF19: 35 | DG19: 28 | DH19: 7 | DI19: 4 | DJ19: 34 | DK19: 1 | DL19: 94 | DM19: n/a | DN19: 3 | DO19: 1 | DP19: 47 | DQ19: 20 | DR19: 10 | DS19: 46 | DT19: n/a | DU19: 15 | DV19: 17 | DW19: 39 | DX19: 11 | DY19: 1 | DZ19: 8 | EA19: 7 | EB19: 11 | EC19: 12 | ED19: n/a | EE19: 30 | EF19: 104 | EG19: 5 | EH19: 6 | EI19: 36 | EJ19: 31 | EK19: 27 | EL19: 35 | EM19: 42 | EN19: 6 | EO19: 15 | EP19: 74 | EQ19: 35
A20: Norway | B20: NOR | C20: Europe | D20: High-income | E20: 106694.12 | F20: 5519000 | G20: 69.696212 | H20: NO | I20: 14 | J20: 59.943008 | K20: 54.943257 | L20: 89.660562 | M20: 74.238022 | N20: 18 | O20: 23 | P20: 2 | Q20: 12 | R20: 79.805097 | S20: 54.361598 | T20: 45.662329 | U20: 49.330737 | V20: 45.953285 | W20: 69.54575 | X20: 93.599346 | Y20: 91.831811 | Z20: 83.55053 | AA20: 46.435169 | AB20: 91.720607 | AC20: 84.558288 | AD20: 20 | AE20: 11 | AF20: 34 | AG20: 72 | AH20: 29 | AI20: 7 | AJ20: 4 | AK20: 2 | AL20: 13 | AM20: 27 | AN20: 3 | AO20: 14 | AP20: 84.568517 | AQ20: 97.608819 | AR20: 29.134186 | AS20: 99.473684 | AT20: 68.045377 | AU20: 100 | AV20: 80.70866 | AW20: 61.695166 | AX20: 70.98308 | AY20: 4.0594889 | AZ20: n/a | BA20: 73.5 | BB20: 15.584747 | BC20: 47.902239 | BD20: 10.562807 | BE20: 78.698401 | BF20: 83.304182 | BG20: n/a | BH20: 24.757558 | BI20: 82.431376 | BJ20: 17.865062 | BK20: 52.302026 | BL20: 31.214677 | BM20: 89.379339 | BN20: n/a | BO20: 90.119183 | BP20: 29.138727 | BQ20: 84.381419 | BR20: 96.416618 | BS20: n/a | BT20: 100 | BU20: 82.205797 | BV20: 93.4375 | BW20: n/a | BX20: 100 | BY20: 91.683949 | BZ20: 85.505713 | CA20: 97.219415 | CB20: 67.926462 | CC20: n/a | CD20: 28.355438 | CE20: 60.340838 | CF20: 80.58781 | CG20: 16.45659 | CH20: 89.410188 | CI20: 93.489583 | CJ20: 93.112245 | CK20: 91.411857 | CL20: 100 | CM20: 56.690343 | CN20: 95.454545 | CO20: 86.544672 | CP20: 99.087184 | CQ20: 27 | CR20: 11 | CS20: 72 | CT20: 29 | CU20: 83 | CV20: 1 | CW20: 6 | CX20: 11 | CY20: 31 | CZ20: 70 | DA20: n/a | DB20: 16 | DC20: 23 | DD20: 11 | DE20: 74 | DF20: 16 | DG20: 16 | DH20: n/a | DI20: 29 | DJ20: 23 | DK20: 31 | DL20: 27 | DM20: 23 | DN20: 18 | DO20: n/a | DP20: 5 | DQ20: 18 | DR20: 28 | DS20: 37 | DT20: n/a | DU20: 1 | DV20: 13 | DW20: 10 | DX20: n/a | DY20: 1 | DZ20: 11 | EA20: 22 | EB20: 10 | EC20: 31 | ED20: n/a | EE20: 22 | EF20: 47 | EG20: 8 | EH20: 55 | EI20: 7 | EJ20: 9 | EK20: 8 | EL20: 6 | EM20: 1 | EN20: 33 | EO20: 20 | EP20: 23 | EQ20: 2
A21: Ireland | B21: IRL | C21: Europe | D21: High-income | E21: 147878.19 | F21: 5197000 | G21: 69.375584 | H21: IE | I21: 15 | J21: 58.125036 | K21: 52.258376 | L21: 84.431486 | M21: 82.68744 | N21: 24 | O21: 30 | P21: 14 | Q21: 2 | R21: 76.257577 | S21: 44.761875 | T21: 53.355655 | U21: 55.357532 | V21: 47.892847 | W21: 53.524747 | X21: 88.6324 | Y21: 79.174995 | Z21: 85.487063 | AA21: 71.433501 | AB21: 84.787498 | AC21: 91.841319 | AD21: 39 | AE21: 28 | AF21: 21 | AG21: 47 | AH21: 27 | AI21: 29 | AJ21: 11 | AK21: 21 | AL21: 8 | AM21: 4 | AN21: 10 | AO21: 1 | AP21: 98.118497 | AQ21: 100 | AR21: 17.984597 | AS21: 99.473684 | AT21: 65.711108 | AU21: n/a | AV21: 65.659883 | AW21: 38.374056 | AX21: 72.131091 | AY21: 2.8824728 | AZ21: 79.090933 | BA21: 70.5 | BB21: 9.8906852 | BC21: 53.941002 | BD21: 4.6540531 | BE21: 87.08806 | BF21: 79.431311 | BG21: n/a | BH21: 50.256703 | BI21: 94.68965 | BJ21: 22.662015 | BK21: 48.878353 | BL21: 25.341372 | BM21: 85.175828 | BN21: 68.282797 | BO21: 35.761545 | BP21: 24.878819 | BQ21: 94.321086 | BR21: 89.052023 | BS21: n/a | BT21: 82.52409 | BU21: 86.005546 | BV21: 98.125 | BW21: 63.071679 | BX21: 100 | BY21: 48.67275 | BZ21: 91.303428 | CA21: 93.082601 | CB21: 72.075159 | CC21: n/a | CD21: 43.220122 | CE21: 62.093036 | CF21: 80.420847 | CG21: 100 | CH21: 81.076854 | CI21: 86.197917 | CJ21: 86.734694 | CK21: 87.440753 | CL21: 100 | CM21: 68.874514 | CN21: 100 | CO21: 100 | CP21: 96.981526 | CQ21: 2 | CR21: 1 | CS21: 98 | CT21: 29 | CU21: 98 | CV21: n/a | CW21: 14 | CX21: 23 | CY21: 26 | CZ21: 77 | DA21: 23 | DB21: 18 | DC21: 28 | DD21: 3 | DE21: 96 | DF21: 4 | DG21: 32 | DH21: n/a | DI21: 7 | DJ21: 3 | DK21: 27 | DL21: 35 | DM21: 31 | DN21: 29 | DO21: 13 | DP21: 66 | DQ21: 25 | DR21: 11 | DS21: 64 | DT21: n/a | DU21: 12 | DV21: 8 | DW21: 3 | DX21: 35 | DY21: 1 | DZ21: 90 | EA21: 15 | EB21: 24 | EC21: 11 | ED21: n/a | EE21: 18 | EF21: 41 | EG21: 9 | EH21: 1 | EI21: 15 | EJ21: 30 | EK21: 17 | EL21: 17 | EM21: 1 | EN21: 8 | EO21: 1 | EP21: 1 | EQ21: 4
A22: Israel | B22: ISR | C22: Europe | D22: High-income | E22: 55766.414 | F22: 9256000 | G22: 69.259843 | H22: IL | I22: 16 | J22: 54.784515 | K22: 69.53497 | L22: 72.938877 | M22: 79.78101 | N22: 31 | O22: 3 | P22: 38 | Q22: 6 | R22: 74.783033 | S22: 47.401622 | T22: 42.16889 | U22: 70.982716 | V22: 64.989094 | W22: 72.633101 | X22: 75.546625 | Y22: 73.149198 | Z22: 70.120808 | AA22: 85.436256 | AB22: 76.801223 | AC22: 77.105552 | AD22: 44 | AE22: 22 | AF22: 41 | AG22: 7 | AH22: 5 | AI22: 5 | AJ22: 40 | AK22: 35 | AL22: 52 | AM22: 1 | AN22: 27 | AO22: 36 | AP22: 78.106153 | AQ22: 84.947446 | AR22: 32.117232 | AS22: 94.736842 | AT22: 66.784356 | AU22: 92.006172 | AV22: 79.860081 | AW22: 18.039229 | AX22: 84.762643 | AY22: 6.944534 | AZ22: n/a | BA22: 96.25 | BB22: 11.898942 | BC22: 18.357729 | BD22: 20.545402 | BE22: 87.707869 | BF22: 75.677593 | BG22: n/a | BH22: 100 | BI22: 76.956654 | BJ22: 100 | BK22: 49.008345 | BL22: 33.991377 | BM22: 82.449682 | BN22: 46.438697 | BO22: 61.644024 | BP22: 100 | BQ22: 75.881497 | BR22: 92.500499 | BS22: n/a | BT22: 58.257878 | BU22: 70.300947 | BV22: 40.9375 | BW22: 91.639438 | BX22: 75 | BY22: 87.868105 | BZ22: 68.112569 | CA22: 88.243195 | CB22: 64.334112 | CC22: 59.793355 | CD22: 96.566841 | CE22: 59.741927 | CF22: n/a | CG22: 100 | CH22: 88.784629 | CI22: 64.583333 | CJ22: 64.030612 | CK22: 90.040798 | CL22: 100 | CM22: 53.003625 | CN22: 71.818182 | CO22: 86.329386 | CP22: 94.542028 | CQ22: 40 | CR22: 38 | CS22: 62 | CT22: 63 | CU22: 92 | CV22: 47 | CW22: 8 | CX22: 36 | CY22: 2 | CZ22: 56 | DA22: n/a | DB22: 2 | DC22: 27 | DD22: 59 | DE22: 50 | DF22: 3 | DG22: 46 | DH22: n/a | DI22: 1 | DJ22: 32 | DK22: 1 | DL22: 34 | DM22: 21 | DN22: 35 | DO22: 36 | DP22: 25 | DQ22: 1 | DR22: 42 | DS22: 51 | DT22: n/a | DU22: 37 | DV22: 27 | DW22: 111 | DX22: 4 | DY22: 72 | DZ22: 16 | EA22: 53 | EB22: 34 | EC22: 60 | ED22: 46 | EE22: 7 | EF22: 49 | EG22: n/a | EH22: 1 | EI22: 8 | EJ22: 81 | EK22: 74 | EL22: 10 | EM22: 1 | EN22: 36 | EO22: 81 | EP22: 25 | EQ22: 10
A23: Australia | B23: AUS | C23: Asia & Pacific | D23: High-income | E23: 71430.886 | F23: 26451000 | G23: 69.016043 | H23: AU | I23: 17 | J23: 59.697319 | K23: 59.509817 | L23: 86.284808 | M23: 70.572228 | N23: 19 | O23: 14 | P23: 10 | Q23: 18 | R23: 80.278127 | S23: 54.302876 | T23: 44.510954 | U23: 55.463571 | V23: 56.394776 | W23: 66.671106 | X23: 90.315861 | Y23: 86.116593 | Z23: 82.421969 | AA23: 46.71379 | AB23: 81.599452 | AC23: 83.40344 | AD23: 18 | AE23: 12 | AF23: 39 | AG23: 46 | AH23: 15 | AI23: 13 | AJ23: 9 | AK23: 11 | AL23: 18 | AM23: 26 | AN23: 16 | AO23: 17 | AP23: 73.519732 | AQ23: 100 | AR23: 36.021684 | AS23: 98.421053 | AT23: 73.706295 | AU23: 100 | AV23: 47.251227 | AW23: 68.822132 | AX23: 70.485689 | AY23: 30.652455 | AZ23: 85.729486 | BA23: 65.75 | BB23: 7.8740039 | BC23: 18.690327 | BD23: 32.077735 | BE23: 76.211613 | BF23: 81.220384 | BG23: n/a | BH23: 32.344552 | BI23: 80.253173 | BJ23: 31.668589 | BK23: 63.815731 | BL23: 49.84161 | BM23: 90.638948 | BN23: 69.740714 | BO23: 80.164267 | BP23: 26.140494 | BQ23: 86.169142 | BR23: 95.485959 | BS23: n/a | BT23: 89.292482 | BU23: 90.831335 | BV23: 89.6875 | BW23: 73.954632 | BX23: 100 | BY23: 76.109498 | BZ23: 85.505713 | CA23: 95.763206 | CB23: 65.996988 | CC23: n/a | CD23: 21.826338 | CE23: 71.72655 | CF23: 82.795886 | CG23: 10.506388 | CH23: 82.975871 | CI23: 79.817708 | CJ23: 74.489796 | CK23: 89.519759 | CL23: 100 | CM23: 66.202143 | CN23: 95.454545 | CO23: 74.058127 | CP23: 95.797889 | CQ23: 54 | CR23: 1 | CS23: 50 | CT23: 48 | CU23: 51 | CV23: 1 | CW23: 23 | CX23: 9 | CY23: 35 | CZ23: 27 | DA23: 14 | DB23: 24 | DC23: 31 | DD23: 58 | DE23: 31 | DF23: 21 | DG23: 23 | DH23: n/a | DI23: 21 | DJ23: 27 | DK23: 20 | DL23: 11 | DM23: 8 | DN23: 14 | DO23: 11 | DP23: 10 | DQ23: 24 | DR23: 23 | DS23: 45 | DT23: n/a | DU23: 5 | DV23: 2 | DW23: 19 | DX23: 22 | DY23: 1 | DZ23: 39 | EA23: 22 | EB23: 18 | EC23: 48 | ED23: n/a | EE23: 24 | EF23: 19 | EG23: 6 | EH23: 73 | EI23: 11 | EJ23: 48 | EK23: 48 | EL23: 13 | EM23: 1 | EN23: 10 | EO23: 20 | EP23: 70 | EQ23: 9
A24: Luxembourg | B24: LUX | C24: Europe | D24: High-income | E24: 152394.65 | F24: 665000 | G24: 68.365145 | H24: LU | I24: 18 | J24: 62.818431 | K24: 48.733396 | L24: 86.813056 | M24: 75.095695 | N24: 14 | O24: 35 | P24: 7 | Q24: 10 | R24: 79.14333 | S24: 50.397685 | T24: 58.91428 | U24: 45.507449 | V24: 52.88959 | W24: 47.803149 | X24: 93.426632 | Y24: 92.512223 | Z24: 74.500314 | AA24: 51.842536 | AB24: 86.35926 | AC24: 87.085289 | AD24: 23 | AE24: 16 | AF24: 15 | AG24: 87 | AH24: 20 | AI24: 41 | AJ24: 5 | AK24: 1 | AL24: 39 | AM24: 20 | AN24: 8 | AO24: 5 | AP24: 96.547119 | AQ24: 91.999717 | AR24: 6.2822742 | AS24: 100 | AT24: 80.030869 | AU24: 100 | AV24: 48.209135 | AW24: 82.586215 | AX24: 70.267034 | AY24: 0.52835467 | AZ24: 85.287652 | BA24: 79.5 | BB24: n/a | BC24: 11.955186 | BD24: 1.7231155 | BE24: 60.112203 | BF24: 50.770632 | BG24: n/a | BH24: 69.423845 | BI24: 83.339851 | BJ24: 39.911505 | BK24: 35.417415 | BL24: n/a | BM24: 70.589863 | BN24: n/a | BO24: 56.586586 | BP24: 16.232998 | BQ24: 88.395347 | BR24: 98.457916 | BS24: n/a | BT24: n/a | BU24: 90.502452 | BV24: 80.3125 | BW24: 100 | BX24: 100 | BY24: 91.746163 | BZ24: 60.865425 | CA24: 96.368711 | CB24: 66.266804 | CC24: n/a | CD24: 62.369428 | CE24: 43.489017 | CF24: 76.132522 | CG24: 25.379177 | CH24: 86.282395 | CI24: 89.453125 | CJ24: 75 | CK24: 91.684518 | CL24: 100 | CM24: 57.652894 | CN24: 100 | CO24: 93.4338 | CP24: 94.508926 | CQ24: 5 | CR24: 25 | CS24: 116 | CT24: 1 | CU24: 22 | CV24: 1 | CW24: 22 | CX24: 5 | CY24: 39 | CZ24: 106 | DA24: 15 | DB24: 10 | DC24: n/a | DD24: 79 | DE24: 115 | DF24: 43 | DG24: 91 | DH24: n/a | DI24: 3 | DJ24: 20 | DK24: 15 | DL24: 90 | DM24: n/a | DN24: 64 | DO24: n/a | DP24: 30 | DQ24: 40 | DR24: 17 | DS24: 26 | DT24: n/a | DU24: n/a | DV24: 3 | DW24: 46 | DX24: 1 | DY24: 1 | DZ24: 10 | EA24: 67 | EB24: 13 | EC24: 46 | ED24: n/a | EE24: 13 | EF24: 91 | EG24: 13 | EH24: 38 | EI24: 9 | EJ24: 17 | EK24: 46 | EL24: 5 | EM24: 1 | EN24: 32 | EO24: 1 | EP24: 6 | EQ24: 11
A25: France | B25: FRA | C25: Europe | D25: High-income | E25: 66060.528 | F25: 66439000 | G25: 68.162698 | H25: FR | I25: 19 | J25: 61.636419 | K25: 59.169449 | L25: 81.987441 | M25: 69.857482 | N25: 15 | O25: 16 | P25: 21 | Q25: 21 | R25: 83.399497 | S25: 46.747651 | T25: 54.76211 | U25: 57.652891 | V25: 53.644704 | W25: 66.210752 | X25: 82.466729 | Y25: 83.053526 | Z25: 80.442067 | AA25: 50.612503 | AB25: 74.364135 | AC25: 84.595809 | AD25: 9 | AE25: 24 | AF25: 18 | AG25: 37 | AH25: 19 | AI25: 14 | AJ25: 25 | AK25: 15 | AL25: 22 | AM25: 22 | AN25: 38 | AO25: 13 | AP25: 88.498653 | AQ25: 98.484296 | AR25: 57.966073 | AS25: 94.736842 | AT25: 77.311622 | AU25: n/a | AV25: 48.570921 | AW25: 37.618984 | AX25: 73.931841 | AY25: 26.86886 | AZ25: 79.78411 | BA25: 67.25 | BB25: 23.815469 | BC25: 48.198861 | BD25: 47.693072 | BE25: 70.889511 | BF25: 79.855565 | BG25: n/a | BH25: 32.173417 | BI25: 66.540111 | BJ25: 18.513209 | BK25: 71.876588 | BL25: 57.648907 | BM25: 81.23218 | BN25: 73.433156 | BO25: 75.771958 | BP25: 34.405715 | BQ25: 88.245895 | BR25: 98.771688 | BS25: n/a | BT25: 60.382605 | BU25: 71.094415 | BV25: 91.5625 | BW25: 81.872431 | BX25: 100 | BY25: 70.738283 | BZ25: 79.707998 | CA25: 96.123553 | CB25: 65.494651 | CC25: n/a | CD25: 43.253469 | CE25: 79.644596 | CF25: 60.797823 | CG25: 18.754122 | CH25: 74.463807 | CI25: 64.973958 | CJ25: 79.591837 | CK25: 87.717444 | CL25: 100 | CM25: 58.32149 | CN25: 100 | CO25: 84.068891 | CP25: 91.985714 | CQ25: 14 | CR25: 8 | CS25: 15 | CT25: 63 | CU25: 32 | CV25: n/a | CW25: 21 | CX25: 25 | CY25: 20 | CZ25: 31 | DA25: 22 | DB25: 22 | DC25: 19 | DD25: 9 | DE25: 11 | DF25: 30 | DG25: 29 | DH25: n/a | DI25: 22 | DJ25: 44 | DK25: 30 | DL25: 6 | DM25: 6 | DN25: 37 | DO25: 4 | DP25: 16 | DQ25: 16 | DR25: 18 | DS25: 23 | DT25: n/a | DU25: 32 | DV25: 25 | DW25: 13 | DX25: 10 | DY25: 1 | DZ25: 46 | EA25: 33 | EB25: 15 | EC25: 53 | ED25: n/a | EE25: 17 | EF25: 9 | EG25: 34 | EH25: 50 | EI25: 30 | EJ25: 80 | EK25: 33 | EL25: 15 | EM25: 1 | EN25: 26 | EO25: 1 | EP25: 37 | EQ25: 14
A26: Belgium | B26: BEL | C26: Europe | D26: High-income | E26: 75882.366 | F26: 11713000 | G26: 67.154411 | H26: BE | I26: 20 | J26: 59.574776 | K26: 55.860504 | L26: 81.033435 | M26: 72.148928 | N26: 21 | O26: 20 | P26: 23 | Q26: 14 | R26: 78.910556 | S26: 45.185474 | T26: 54.628299 | U26: 47.472378 | V26: 55.812665 | W26: 64.296469 | X26: 86.512956 | Y26: 87.409801 | Z26: 69.177548 | AA26: 47.964792 | AB26: 85.282053 | AC26: 83.199939 | AD26: 24 | AE26: 27 | AF26: 19 | AG26: 79 | AH26: 16 | AI26: 17 | AJ26: 17 | AK26: 9 | AL26: 53 | AM26: 23 | AN26: 9 | AO26: 18 | AP26: 85.700993 | AQ26: 95.74159 | AR26: 18.616039 | AS26: 100 | AT26: 73.404716 | AU26: 100 | AV26: 66.094173 | AW26: 47.188818 | AX26: 61.366509 | AY26: 6.0923961 | AZ26: 79.979893 | BA26: 67.5 | BB26: 28.263838 | BC26: 42.769466 | BD26: 13.356585 | BE26: 69.069291 | BF26: 81.622222 | BG26: n/a | BH26: 25.841415 | BI26: 93.439246 | BJ26: 37.21605 | BK26: 56.58834 | BL26: 36.007025 | BM26: 66.607716 | BN26: n/a | BO26: 73.953303 | BP26: 52.328386 | BQ26: 84.650705 | BR26: 96.17891 | BS26: n/a | BT26: 78.709253 | BU26: 71.462762 | BV26: 94.375 | BW26: 82.14032 | BX26: 100 | BY26: 89.070925 | BZ26: 47.820567 | CA26: 94.320324 | CB26: 65.391754 | CC26: n/a | CD26: 26.890069 | CE26: 64.215868 | CF26: 73.351282 | CG26: 27.40195 | CH26: 81.546023 | CI26: 84.765625 | CJ26: 92.346939 | CK26: 86.722082 | CL26: 100 | CM26: 61.618671 | CN26: 100 | CO26: 78.68676 | CP26: 84.988654 | CQ26: 25 | CR26: 18 | CS26: 95 | CT26: 1 | CU26: 53 | CV26: 1 | CW26: 13 | CX26: 18 | CY26: 75 | CZ26: 62 | DA26: 21 | DB26: 21 | DC26: 16 | DD26: 18 | DE26: 68 | DF26: 32 | DG26: 20 | DH26: n/a | DI26: 27 | DJ26: 5 | DK26: 16 | DL26: 22 | DM26: 19 | DN26: 70 | DO26: n/a | DP26: 17 | DQ26: 6 | DR26: 27 | DS26: 40 | DT26: n/a | DU26: 16 | DV26: 24 | DW26: 5 | DX26: 8 | DY26: 1 | DZ26: 14 | EA26: 83 | EB26: 21 | EC26: 54 | ED26: n/a | EE26: 23 | EF26: 35 | EG26: 17 | EH26: 34 | EI26: 14 | EJ26: 32 | EK26: 9 | EL26: 21 | EM26: 1 | EN26: 20 | EO26: 1 | EP26: 51 | EQ26: 28
A27: Austria | B27: AUT | C27: Europe | D27: High-income | E27: 74852.289 | F27: 9130000 | G27: 67.130278 | H27: AT | I27: 21 | J27: 59.679771 | K27: 52.356938 | L27: 82.742875 | M27: 73.741527 | N27: 20 | O27: 29 | P27: 19 | Q27: 13 | R27: 76.860949 | S27: 47.801781 | T27: 54.376584 | U27: 53.231898 | V27: 48.322054 | W27: 55.516861 | X27: 82.393427 | Y27: 85.596345 | Z27: 80.238854 | AA27: 56.21708 | AB27: 80.970882 | AC27: 84.03662 | AD27: 35 | AE27: 21 | AF27: 20 | AG27: 56 | AH27: 26 | AI27: 26 | AJ27: 27 | AK27: 13 | AL27: 23 | AM27: 15 | AN27: 19 | AO27: 15 | AP27: 92.572472 | AQ27: 96.073055 | AR27: 15.99217 | AS27: 89.473684 | AT27: 67.054312 | AU27: 100 | AV27: 58.287963 | AW27: 57.989416 | AX27: 68.545092 | AY27: 6.3846542 | AZ27: 74.896213 | BA27: 64.25 | BB27: 33.209857 | BC27: 45.150264 | BD27: 31.130881 | BE27: 65.03829 | BF27: 83.957509 | BG27: n/a | BH27: 32.800913 | BI27: 91.508851 | BJ27: 24.459413 | BK27: 47.30233 | BL27: 30.017624 | BM27: 80.545229 | BN27: n/a | BO27: 34.164933 | BP27: 51.840421 | BQ27: 86.67118 | BR27: 86.955217 | BS27: n/a | BT27: 73.553884 | BU27: 76.29614 | BV27: 85.9375 | BW27: 80.700388 | BX27: 100 | BY27: 85.047698 | BZ27: 76.809141 | CA27: 97.873832 | CB27: 66.033588 | CC27: n/a | CD27: 60.709153 | CE27: 61.744305 | CF27: 74.887087 | CG27: 27.527774 | CH27: 79.311886 | CI27: 79.6875 | CJ27: 81.122449 | CK27: 86.704071 | CL27: 100 | CM27: 61.622324 | CN27: 95.454545 | CO27: 85.791173 | CP27: 86.556874 | CQ27: 8 | CR27: 16 | CS27: 101 | CT27: 83 | CU27: 89 | CV27: 1 | CW27: 18 | CX27: 13 | CY27: 49 | CZ27: 59 | DA27: 34 | DB27: 26 | DC27: 13 | DD27: 16 | DE27: 35 | DF27: 37 | DG27: 14 | DH27: n/a | DI27: 20 | DJ27: 13 | DK27: 25 | DL27: 43 | DM27: 25 | DN27: 39 | DO27: n/a | DP27: 70 | DQ27: 8 | DR27: 22 | DS27: 66 | DT27: n/a | DU27: 19 | DV27: 19 | DW27: 30 | DX27: 13 | DY27: 1 | DZ27: 20 | EA27: 37 | EB27: 8 | EC27: 47 | ED27: n/a | EE27: 14 | EF27: 43 | EG27: 14 | EH27: 33 | EI27: 17 | EJ27: 49 | EK27: 31 | EL27: 22 | EM27: 1 | EN27: 19 | EO27: 20 | EP27: 29 | EQ27: 23
A28: Iceland | B28: ISL | C28: Europe | D28: High-income | E28: 80466.384 | F28: 388000 | G28: 66.095835 | H28: IS | I28: 22 | J28: 59.538723 | K28: 59.666607 | L28: 85.357302 | M28: 59.820707 | N28: 22 | O28: 13 | P28: 12 | Q28: 41 | R28: 72.998869 | S28: 60.250265 | T28: 45.367035 | U28: 44.316235 | V28: 74.607125 | W28: 60.076461 | X28: 91.014608 | Y28: 77.410426 | Z28: 87.646873 | AA28: 23.836784 | AB28: 93.991417 | AC28: 61.633919 | AD28: 52 | AE28: 6 | AF28: 36 | AG28: 92 | AH28: 2 | AI28: 23 | AJ28: 8 | AK28: 28 | AL28: 4 | AM28: 99 | AN28: 2 | AO28: 71 | AP28: 83.492414 | AQ28: 97.441407 | AR28: 9.1127436 | AS28: 97.368421 | AT28: 77.579358 | AU28: n/a | AV28: 80.408062 | AW28: 100 | AX28: 60.435922 | AY28: 0.1570754 | AZ28: 82.241747 | BA28: 65.75 | BB28: 12.073924 | BC28: 21.40247 | BD28: 2.8362708 | BE28: 82.479458 | BF28: 78.201349 | BG28: n/a | BH28: 13.747861 | BI28: 92.643535 | BJ28: 100 | BK28: 31.177839 | BL28: n/a | BM28: 88.87766 | BN28: n/a | BO28: 49.626131 | BP28: 41.725592 | BQ28: 91.340466 | BR28: 98.589309 | BS28: n/a | BT28: 83.114049 | BU28: 74.371099 | BV28: 85 | BW28: 73.896295 | BX28: 75 | BY28: 78.784737 | BZ28: 95.651714 | CA28: 99.372767 | CB28: 67.916137 | CC28: n/a | CD28: 13.13599 | CE28: 30.752061 | CF28: n/a | CG28: 27.622302 | CH28: 95.062556 | CI28: 94.661458 | CJ28: 92.346939 | CK28: 92.153536 | CL28: 100 | CM28: 45.45925 | CN28: 100 | CO28: 1.0764263 | CP28: 100 | CQ28: 30 | CR28: 12 | CS28: 111 | CT28: 57 | CU28: 29 | CV28: n/a | CW28: 7 | CX28: 1 | CY28: 77 | CZ28: 116 | DA28: 20 | DB28: 24 | DC28: 26 | DD28: 48 | DE28: 109 | DF28: 9 | DG28: 35 | DH28: n/a | DI28: 37 | DJ28: 8 | DK28: 1 | DL28: 106 | DM28: n/a | DN28: 20 | DO28: n/a | DP28: 36 | DQ28: 13 | DR28: 13 | DS28: 24 | DT28: n/a | DU28: 11 | DV28: 22 | DW28: 32 | DX28: 23 | DY28: 72 | DZ28: 29 | EA28: 7 | EB28: 4 | EC28: 35 | ED28: n/a | EE28: 28 | EF28: 123 | EG28: n/a | EH28: 32 | EI28: 3 | EJ28: 7 | EK28: 9 | EL28: 4 | EM28: 1 | EN28: 40 | EO28: 1 | EP28: 125 | EQ28: 1
